Traceback (most recent call last):
  File "/home/pi/Documents/utme-detector/test.py", line 38, in <module>
    sps.start_measurement()
  File "/usr/local/lib/python3.7/dist-packages/sps30/sps30.py", line 166, in start_measurement
    self.bus.i2c_rdwr(write)
  File "/usr/local/lib/python3.7/dist-packages/smbus2/smbus2.py", line 637, in i2c_rdwr
    ioctl(self.fd, I2C_RDWR, ioctl_data)
OSError: [Errno 121] Remote I/O error
